<?xml version="1.0"?>
<robot xmlns:xacro="http://www.ros.org/wiki/xacro"  >

    <xacro:include filename="inertial_macros.xacro" />

    <material name="white">
        <color rgba="1 1 1 1"/>
    </material>

    <material name="orange">
        <color rgba="1 0.3 0.1 1"/>
    </material>

    <material name="blue">
        <color rgba="0.2 0.2 1 1"/>
    </material>

    <material name="black">
        <color rgba="0 0 0 1"/>
    </material>

    <!-- BASE LINK -->

    <link name="base_link">
    </link>

    <!-- CHASSIS LINK -->

    <joint name="chasis_joint" type="fixed">
        <parent link="base_link"/>
        <child link="chassis"/>
        <origin xyz="-0.1 0 0"/>
    </joint>

    <link name="chassis">
        <visual>
            <origin xyz="0.15 0 0.075" rpy="0 0 0"/>
            <geometry>
                <box size="0.3 0.3 0.15"/>
            </geometry>
            <material name="white"/>
        </visual>

        <collision>
            <origin xyz="0.15 0 0.075" rpy="0 0 0"/>
            <geometry>
                <box size="0.3 0.3 0.15"/>
            </geometry>
        </collision>

        <xacro:inertial_box mass="0.5" x="0.3" y="0.3" z="0.15">
            <origin xyz="0.15 0 0.075" rpy="0 0 0"/>
        </xacro:inertial_box>

    </link>

    <!-- LEFT WHEEL LINK -->

    <joint name="left_wheel_joint" type="continuous">
        <parent link="base_link"/>
        <child link="left_wheel"/>
        <origin xyz="0 0.175 0" rpy="-${pi/2} 0 0"/>
        <axis xyz="0 0 1"/>
    </joint>

    <link name="left_wheel">
        <visual>
            <geometry>
                <cylinder length="0.04" radius="0.05" />
            </geometry>
            <material name="blue"/>
        </visual>

        <collison>
            <geometry>
                <cylinder length="0.04" radius="0.05" />
            </geometry>
        </collison>

        <!-- Inertial-->

        <xacro:inertial_cylinder mass="0.1" length="0.04" radius="0.04">
            <origin xyz="0 0 0" rpy="0 0 0"/>
        </xacro:inertial_cylinder>

    </link>

    <!-- LEFT WHEEL2 LINK -->

    <joint name="left2_wheel_joint" type="continuous">
        <parent link="base_link"/>
        <child link="left2_wheel"/>
        <origin xyz="0.15 0.175 0" rpy="-${pi/2} 0 0"/>
        <axis xyz="0 0 1"/>
    </joint>

    <link name="left2_wheel">
        <visual>
            <geometry>
                <cylinder length="0.04" radius="0.05" />
            </geometry>
            <material name="blue"/>
        </visual>

        <collision>
            <geometry>
                <cylinder length="0.04" radius="0.05" />
            </geometry>
        </collision>

        <!-- Inertial-->
        <xacro:inertial_cylinder mass="0.1" length="0.04" radius="0.04">
            <origin xyz="0 0 0" rpy="0 0 0"/>
        </xacro:inertial_cylinder>

    </link>

    <!-- RIGHT WHEEL LINK -->

    <joint name="right_wheel_joint" type="continuous">
        <parent link="base_link"/>
        <child link="right_wheel"/>
        <origin xyz="0 -0.175 0" rpy="${pi/2} 0 0"/>
        <axis xyz="0 0 -1"/>
    </joint>

    <link name="right_wheel">
        <visual>
            <geometry>
                <cylinder length="0.04" radius="0.05" />
            </geometry>
            <material name="blue"/>
        </visual>

        <collision>
            <geometry>
                <cylinder length="0.04" radius="0.05" />
            </geometry>
        </collision>

        <!-- Inertial-->
        <xacro:inertial_cylinder mass="0.1" length="0.04" radius="0.04">
            <origin xyz="0 0 0" rpy="0 0 0"/>
        </xacro:inertial_cylinder>

    </link>

    <!-- RIGHT WHEEL2 LINK -->

    <joint name="right2_wheel_joint" type="continuous">
        <parent link="base_link"/>
        <child link="right2_wheel"/>
        <origin xyz="0.15 -0.175 0" rpy="${pi/2} 0 0"/>
        <axis xyz="0 0 -1"/>
    </joint>

    <link name="right2_wheel">
        <visual>
            <geometry>
                <cylinder length="0.04" radius="0.05" />
            </geometry>
            <material name="blue"/>
        </visual>
    </link>

    <!-- CASTER WHEEL -->
        <!-- Uncomment if needed -->
    <!-- <joint name="caster_wheel_joint" type="fixed">
        <parent link="chassis"/>
        <child link="caster_wheel"/>
        <origin xyz="0.24 0 0" rpy="0 0 0"/>
    </joint>

    <link name="caster_wheel">
        <visual>
            <geometry>
                <sphere radius="0.05" />
            </geometry>
            <material name="black"/>
        </visual>
        
        <collison>
            <geometry>
                <sphere radius="0.05" />
            </geometry>
        </collision>

        <xacro:inertial_cylinder mass="0.1" radius="0.04">
            <origin xyz="0 0 0" rpy="0 0 0"/>
        </xacro:inertial_cylinder>

    </link> -->

</robot>